2024-09-26 16:20:10,740:DEBUG:certbot._internal.main:certbot version: 2.11.0
2024-09-26 16:20:10,740:DEBUG:certbot._internal.main:Location of certbot entry point: /usr/local/bin/certbot
2024-09-26 16:20:10,740:DEBUG:certbot._internal.main:Arguments: ['--webroot', '--webroot-path=/var/www/html', '--email', 'youremail@domain.com', '--agree-tos', '--no-eff-email', '-d', 'domain.com', '-d', 'www.domain.com']
2024-09-26 16:20:10,741:DEBUG:certbot._internal.main:Discovered plugins: PluginsRegistry(PluginEntryPoint#manual,PluginEntryPoint#null,PluginEntryPoint#standalone,PluginEntryPoint#webroot)
2024-09-26 16:20:10,748:DEBUG:certbot._internal.log:Root logging level set at 30
2024-09-26 16:20:10,749:DEBUG:certbot._internal.plugins.selection:Requested authenticator webroot and installer None
2024-09-26 16:20:10,749:DEBUG:certbot._internal.plugins.selection:Single candidate plugin: * webroot
Description: Saves the necessary validation files to a .well-known/acme-challenge/ directory within the nominated webroot path. A seperate HTTP server must be running and serving files from the webroot path. HTTP challenge only (wildcards not supported).
Interfaces: Authenticator, Plugin
Entry point: EntryPoint(name='webroot', value='certbot._internal.plugins.webroot:Authenticator', group='certbot.plugins')
Initialized: <certbot._internal.plugins.webroot.Authenticator object at 0x7ff116a96840>
Prep: True
2024-09-26 16:20:10,750:DEBUG:certbot._internal.plugins.selection:Selected authenticator <certbot._internal.plugins.webroot.Authenticator object at 0x7ff116a96840> and installer None
2024-09-26 16:20:10,750:INFO:certbot._internal.plugins.selection:Plugins selected: Authenticator webroot, Installer None
2024-09-26 16:20:10,783:DEBUG:certbot._internal.main:Picked account: <Account(RegistrationResource(body=Registration(key=None, contact=(), agreement=None, status=None, terms_of_service_agreed=None, only_return_existing=None, external_account_binding=None), uri='https://acme-v02.api.letsencrypt.org/acme/acct/1968306146', new_authzr_uri=None, terms_of_service=None), 2d6453d092be90519c926000b0ac3e72, Meta(creation_dt=datetime.datetime(2024, 9, 26, 14, 17, 29, tzinfo=<UTC>), creation_host='d8d805ac1f54', register_to_eff=None))>
2024-09-26 16:20:10,784:DEBUG:acme.client:Sending GET request to https://acme-v02.api.letsencrypt.org/directory.
2024-09-26 16:20:10,785:DEBUG:urllib3.connectionpool:Starting new HTTPS connection (1): acme-v02.api.letsencrypt.org:443
2024-09-26 16:20:11,249:DEBUG:urllib3.connectionpool:https://acme-v02.api.letsencrypt.org:443 "GET /directory HTTP/1.1" 200 746
2024-09-26 16:20:11,249:DEBUG:acme.client:Received response:
HTTP 200
Server: nginx
Date: Thu, 26 Sep 2024 16:20:11 GMT
Content-Type: application/json
Content-Length: 746
Connection: keep-alive
Cache-Control: public, max-age=0, no-cache
X-Frame-Options: DENY
Strict-Transport-Security: max-age=604800

{
  "keyChange": "https://acme-v02.api.letsencrypt.org/acme/key-change",
  "kgVBuf2rJM8": "https://community.letsencrypt.org/t/adding-random-entries-to-the-directory/33417",
  "meta": {
    "caaIdentities": [
      "letsencrypt.org"
    ],
    "termsOfService": "https://letsencrypt.org/documents/LE-SA-v1.4-April-3-2024.pdf",
    "website": "https://letsencrypt.org"
  },
  "newAccount": "https://acme-v02.api.letsencrypt.org/acme/new-acct",
  "newNonce": "https://acme-v02.api.letsencrypt.org/acme/new-nonce",
  "newOrder": "https://acme-v02.api.letsencrypt.org/acme/new-order",
  "renewalInfo": "https://acme-v02.api.letsencrypt.org/draft-ietf-acme-ari-03/renewalInfo",
  "revokeCert": "https://acme-v02.api.letsencrypt.org/acme/revoke-cert"
}
2024-09-26 16:20:11,250:DEBUG:certbot._internal.display.obj:Notifying user: Requesting a certificate for domain.com and www.domain.com
2024-09-26 16:20:11,253:DEBUG:acme.client:Requesting fresh nonce
2024-09-26 16:20:11,253:DEBUG:acme.client:Sending HEAD request to https://acme-v02.api.letsencrypt.org/acme/new-nonce.
2024-09-26 16:20:11,405:DEBUG:urllib3.connectionpool:https://acme-v02.api.letsencrypt.org:443 "HEAD /acme/new-nonce HTTP/1.1" 200 0
2024-09-26 16:20:11,405:DEBUG:acme.client:Received response:
HTTP 200
Server: nginx
Date: Thu, 26 Sep 2024 16:20:11 GMT
Connection: keep-alive
Cache-Control: public, max-age=0, no-cache
Link: <https://acme-v02.api.letsencrypt.org/directory>;rel="index"
Replay-Nonce: fCBw7MtQwBYAcdtVr_LufSQcRlfexYyI_-oYikDBVJ7m8Heltzg
X-Frame-Options: DENY
Strict-Transport-Security: max-age=604800


2024-09-26 16:20:11,406:DEBUG:acme.client:Storing nonce: fCBw7MtQwBYAcdtVr_LufSQcRlfexYyI_-oYikDBVJ7m8Heltzg
2024-09-26 16:20:11,406:DEBUG:acme.client:JWS payload:
b'{\n  "identifiers": [\n    {\n      "type": "dns",\n      "value": "domain.com"\n    },\n    {\n      "type": "dns",\n      "value": "www.domain.com"\n    }\n  ]\n}'
2024-09-26 16:20:11,408:DEBUG:acme.client:Sending POST request to https://acme-v02.api.letsencrypt.org/acme/new-order:
{
  "protected": "eyJhbGciOiAiUlMyNTYiLCAia2lkIjogImh0dHBzOi8vYWNtZS12MDIuYXBpLmxldHNlbmNyeXB0Lm9yZy9hY21lL2FjY3QvMTk2ODMwNjE0NiIsICJub25jZSI6ICJmQ0J3N010UXdCWUFjZHRWcl9MdWZTUWNSbGZleFl5SV8tb1lpa0RCVko3bThIZWx0emciLCAidXJsIjogImh0dHBzOi8vYWNtZS12MDIuYXBpLmxldHNlbmNyeXB0Lm9yZy9hY21lL25ldy1vcmRlciJ9",
  "signature": "X1QEyWtoQOXFBPwzUSdC8FYwFGPxJ0baoa4jPsuZg5vOL1wRfu-sp6QypRrojKuIX2_o5UEMo_nP8-WIuIuG6oUz-KtD1bHIeisej-fEG7CvBvXAZgqRyfyxBESc0pogb3eVeEZNBqNv5dauEZhY2BFgI5c8VmHi4boPBVGogrUXGgLExaOfiIRJigHso3hLrUse0s2JiXuOTMFI3gnSnZXVTNv730RLyFUFzrP5coAg8LhJFDjNs2LFmZZf8YLcpDp1bKiSceVNZjtYF3mWqdewHHfkn8xLVbX0w7kp8TLTPbzlItF6s0el9aX6uMgcxVnTcIAZYMQoCGskrCqnLQ",
  "payload": "ewogICJpZGVudGlmaWVycyI6IFsKICAgIHsKICAgICAgInR5cGUiOiAiZG5zIiwKICAgICAgInZhbHVlIjogImRvbWFpbi5jb20iCiAgICB9LAogICAgewogICAgICAidHlwZSI6ICJkbnMiLAogICAgICAidmFsdWUiOiAid3d3LmRvbWFpbi5jb20iCiAgICB9CiAgXQp9"
}
2024-09-26 16:20:11,582:DEBUG:urllib3.connectionpool:https://acme-v02.api.letsencrypt.org:443 "POST /acme/new-order HTTP/1.1" 429 255
2024-09-26 16:20:11,583:DEBUG:acme.client:Received response:
HTTP 429
Server: nginx
Date: Thu, 26 Sep 2024 16:20:11 GMT
Content-Type: application/problem+json
Content-Length: 255
Connection: keep-alive
Boulder-Requester: 1968306146
Cache-Control: public, max-age=0, no-cache
Link: <https://acme-v02.api.letsencrypt.org/directory>;rel="index", <https://letsencrypt.org/docs/rate-limits>;rel="help"
Replay-Nonce: 4OmWUlyUmvxyISZXSCjQgFe9t6QtPfKmnd_Z1Aj7-Nmtj5Y3kmk
Retry-After: 569

{
  "type": "urn:ietf:params:acme:error:rateLimited",
  "detail": "too many failed authorizations (5) for \"domain.com\" in the last 1h0m0s, retry after 2024-09-26 16:29:40 UTC: see https://letsencrypt.org/docs/failed-validation-limit/",
  "status": 429
}
2024-09-26 16:20:11,583:DEBUG:certbot._internal.log:Exiting abnormally:
Traceback (most recent call last):
  File "/usr/local/bin/certbot", line 33, in <module>
    sys.exit(load_entry_point('certbot', 'console_scripts', 'certbot')())
             ^^^^^^^^^^^^^^^^^^^^^^^^^^^^^^^^^^^^^^^^^^^^^^^^^^^^^^^^^^^
  File "/opt/certbot/src/certbot/certbot/main.py", line 19, in main
    return internal_main.main(cli_args)
           ^^^^^^^^^^^^^^^^^^^^^^^^^^^^
  File "/opt/certbot/src/certbot/certbot/_internal/main.py", line 1894, in main
    return config.func(config, plugins)
           ^^^^^^^^^^^^^^^^^^^^^^^^^^^^
  File "/opt/certbot/src/certbot/certbot/_internal/main.py", line 1600, in certonly
    lineage = _get_and_save_cert(le_client, config, domains, certname, lineage)
              ^^^^^^^^^^^^^^^^^^^^^^^^^^^^^^^^^^^^^^^^^^^^^^^^^^^^^^^^^^^^^^^^^
  File "/opt/certbot/src/certbot/certbot/_internal/main.py", line 143, in _get_and_save_cert
    lineage = le_client.obtain_and_enroll_certificate(domains, certname)
              ^^^^^^^^^^^^^^^^^^^^^^^^^^^^^^^^^^^^^^^^^^^^^^^^^^^^^^^^^^
  File "/opt/certbot/src/certbot/certbot/_internal/client.py", line 517, in obtain_and_enroll_certificate
    cert, chain, key, _ = self.obtain_certificate(domains)
                          ^^^^^^^^^^^^^^^^^^^^^^^^^^^^^^^^
  File "/opt/certbot/src/certbot/certbot/_internal/client.py", line 428, in obtain_certificate
    orderr = self._get_order_and_authorizations(csr.data, self.config.allow_subset_of_names)
             ^^^^^^^^^^^^^^^^^^^^^^^^^^^^^^^^^^^^^^^^^^^^^^^^^^^^^^^^^^^^^^^^^^^^^^^^^^^^^^^
  File "/opt/certbot/src/certbot/certbot/_internal/client.py", line 478, in _get_order_and_authorizations
    orderr = self.acme.new_order(csr_pem)
             ^^^^^^^^^^^^^^^^^^^^^^^^^^^^
  File "/opt/certbot/src/acme/acme/client.py", line 137, in new_order
    response = self._post(self.directory['newOrder'], order)
               ^^^^^^^^^^^^^^^^^^^^^^^^^^^^^^^^^^^^^^^^^^^^^
  File "/opt/certbot/src/acme/acme/client.py", line 365, in _post
    return self.net.post(*args, **kwargs)
           ^^^^^^^^^^^^^^^^^^^^^^^^^^^^^^
  File "/opt/certbot/src/acme/acme/client.py", line 738, in post
    return self._post_once(*args, **kwargs)
           ^^^^^^^^^^^^^^^^^^^^^^^^^^^^^^^^
  File "/opt/certbot/src/acme/acme/client.py", line 751, in _post_once
    response = self._check_response(response, content_type=content_type)
               ^^^^^^^^^^^^^^^^^^^^^^^^^^^^^^^^^^^^^^^^^^^^^^^^^^^^^^^^^
  File "/opt/certbot/src/acme/acme/client.py", line 602, in _check_response
    raise messages.Error.from_json(jobj)
acme.messages.Error: urn:ietf:params:acme:error:rateLimited :: There were too many requests of a given type :: too many failed authorizations (5) for "domain.com" in the last 1h0m0s, retry after 2024-09-26 16:29:40 UTC: see https://letsencrypt.org/docs/failed-validation-limit/
2024-09-26 16:20:11,585:ERROR:certbot._internal.log:An unexpected error occurred:
2024-09-26 16:20:11,585:ERROR:certbot._internal.log:too many failed authorizations (5) for "domain.com" in the last 1h0m0s, retry after 2024-09-26 16:29:40 UTC: see https://letsencrypt.org/docs/failed-validation-limit/
